<?xml version="1.0" encoding="UTF-8"?>
<!-- Generated by org.testng.reporters.JUnitReportReporter -->
<testsuite skipped="0" hostname="MAVLT1168" name="testng_assignment.TestNG_Assertion" tests="4" failures="3" timestamp="2020-06-26T01:56:06 IST" time="16.556" errors="0">
  <testcase name="TestNG_Assertion_AssertEquals" time="4.368" classname="testng_assignment.TestNG_Assertion"/>
  <system-out>
-------------- assertTrue vaidation passed----------  </system-out>
  <testcase name="TestNG_Assertion_assertFalse" time="4.085" classname="testng_assignment.TestNG_Assertion">
    <failure type="java.lang.AssertionError" message="The assertFalse condition :   expected [false] but found [true]">
      <![CDATA[java.lang.AssertionError: The assertFalse condition :   expected [false] but found [true]
at org.testng.Assert.fail(Assert.java:97)
at org.testng.Assert.failNotEquals(Assert.java:969)
at org.testng.Assert.assertFalse(Assert.java:65)
at testng_assignment.TestNG_Assertion.TestNG_Assertion_assertFalse(TestNG_Assertion.java:61)
at sun.reflect.NativeMethodAccessorImpl.invoke0(Native Method)
at sun.reflect.NativeMethodAccessorImpl.invoke(Unknown Source)
at sun.reflect.DelegatingMethodAccessorImpl.invoke(Unknown Source)
at java.lang.reflect.Method.invoke(Unknown Source)
at org.testng.internal.MethodInvocationHelper.invokeMethod(MethodInvocationHelper.java:134)
at org.testng.internal.TestInvoker.invokeMethod(TestInvoker.java:597)
at org.testng.internal.TestInvoker.invokeTestMethod(TestInvoker.java:173)
at org.testng.internal.MethodRunner.runInSequence(MethodRunner.java:46)
at org.testng.internal.TestInvoker$MethodInvocationAgent.invoke(TestInvoker.java:816)
at org.testng.internal.TestInvoker.invokeTestMethods(TestInvoker.java:146)
at org.testng.internal.TestMethodWorker.invokeTestMethods(TestMethodWorker.java:146)
at org.testng.internal.TestMethodWorker.run(TestMethodWorker.java:128)
at java.util.concurrent.ThreadPoolExecutor.runWorker(Unknown Source)
at java.util.concurrent.ThreadPoolExecutor$Worker.run(Unknown Source)
at java.lang.Thread.run(Unknown Source)
]]>
    </failure>
  </testcase> <!-- TestNG_Assertion_assertFalse -->
  <system-out>
26-Jun-2020 01:55:58 AM : java.lang.AssertionError: The assertFalse condition :   expected [false] but found [true]
	at org.testng.Assert.fail(Assert.java:97)
	at org.testng.Assert.failNotEquals(Assert.java:969)
	at org.testng.Assert.assertFalse(Assert.java:65)
	at testng_assignment.TestNG_Assertion.TestNG_Assertion_assertFalse(TestNG_Assertion.java:61)
	at sun.reflect.NativeMethodAccessorImpl.invoke0(Native Method)
	at sun.reflect.NativeMethodAccessorImpl.invoke(Unknown Source)
	at sun.reflect.DelegatingMethodAccessorImpl.invoke(Unknown Source)
	at java.lang.reflect.Method.invoke(Unknown Source)
	at org.testng.internal.MethodInvocationHelper.invokeMethod(MethodInvocationHelper.java:134)
	at org.testng.internal.TestInvoker.invokeMethod(TestInvoker.java:597)
	at org.testng.internal.TestInvoker.invokeTestMethod(TestInvoker.java:173)
	at org.testng.internal.MethodRunner.runInSequence(MethodRunner.java:46)
	at org.testng.internal.TestInvoker$MethodInvocationAgent.invoke(TestInvoker.java:816)
	at org.testng.internal.TestInvoker.invokeTestMethods(TestInvoker.java:146)
	at org.testng.internal.TestMethodWorker.invokeTestMethods(TestMethodWorker.java:146)
	at org.testng.internal.TestMethodWorker.run(TestMethodWorker.java:128)
	at java.util.concurrent.ThreadPoolExecutor.runWorker(Unknown Source)
	at java.util.concurrent.ThreadPoolExecutor$Worker.run(Unknown Source)
	at java.lang.Thread.run(Unknown Source)
  </system-out>
  <testcase name="TestNG_Assertion_assertTrue" time="4.034" classname="testng_assignment.TestNG_Assertion">
    <failure type="java.lang.AssertionError" message="The assertTrue condition :   expected [true] but found [false]">
      <![CDATA[java.lang.AssertionError: The assertTrue condition :   expected [true] but found [false]
at org.testng.Assert.fail(Assert.java:97)
at org.testng.Assert.failNotEquals(Assert.java:969)
at org.testng.Assert.assertTrue(Assert.java:43)
at testng_assignment.TestNG_Assertion.TestNG_Assertion_assertTrue(TestNG_Assertion.java:34)
at sun.reflect.NativeMethodAccessorImpl.invoke0(Native Method)
at sun.reflect.NativeMethodAccessorImpl.invoke(Unknown Source)
at sun.reflect.DelegatingMethodAccessorImpl.invoke(Unknown Source)
at java.lang.reflect.Method.invoke(Unknown Source)
at org.testng.internal.MethodInvocationHelper.invokeMethod(MethodInvocationHelper.java:134)
at org.testng.internal.TestInvoker.invokeMethod(TestInvoker.java:597)
at org.testng.internal.TestInvoker.invokeTestMethod(TestInvoker.java:173)
at org.testng.internal.MethodRunner.runInSequence(MethodRunner.java:46)
at org.testng.internal.TestInvoker$MethodInvocationAgent.invoke(TestInvoker.java:816)
at org.testng.internal.TestInvoker.invokeTestMethods(TestInvoker.java:146)
at org.testng.internal.TestMethodWorker.invokeTestMethods(TestMethodWorker.java:146)
at org.testng.internal.TestMethodWorker.run(TestMethodWorker.java:128)
at java.util.concurrent.ThreadPoolExecutor.runWorker(Unknown Source)
at java.util.concurrent.ThreadPoolExecutor$Worker.run(Unknown Source)
at java.lang.Thread.run(Unknown Source)
]]>
    </failure>
  </testcase> <!-- TestNG_Assertion_assertTrue -->
  <system-out>
26-Jun-2020 01:56:06 AM : java.lang.AssertionError: The assertTrue condition :   expected [true] but found [false]
	at org.testng.Assert.fail(Assert.java:97)
	at org.testng.Assert.failNotEquals(Assert.java:969)
	at org.testng.Assert.assertTrue(Assert.java:43)
	at testng_assignment.TestNG_Assertion.TestNG_Assertion_assertTrue(TestNG_Assertion.java:34)
	at sun.reflect.NativeMethodAccessorImpl.invoke0(Native Method)
	at sun.reflect.NativeMethodAccessorImpl.invoke(Unknown Source)
	at sun.reflect.DelegatingMethodAccessorImpl.invoke(Unknown Source)
	at java.lang.reflect.Method.invoke(Unknown Source)
	at org.testng.internal.MethodInvocationHelper.invokeMethod(MethodInvocationHelper.java:134)
	at org.testng.internal.TestInvoker.invokeMethod(TestInvoker.java:597)
	at org.testng.internal.TestInvoker.invokeTestMethod(TestInvoker.java:173)
	at org.testng.internal.MethodRunner.runInSequence(MethodRunner.java:46)
	at org.testng.internal.TestInvoker$MethodInvocationAgent.invoke(TestInvoker.java:816)
	at org.testng.internal.TestInvoker.invokeTestMethods(TestInvoker.java:146)
	at org.testng.internal.TestMethodWorker.invokeTestMethods(TestMethodWorker.java:146)
	at org.testng.internal.TestMethodWorker.run(TestMethodWorker.java:128)
	at java.util.concurrent.ThreadPoolExecutor.runWorker(Unknown Source)
	at java.util.concurrent.ThreadPoolExecutor$Worker.run(Unknown Source)
	at java.lang.Thread.run(Unknown Source)
  </system-out>
  <testcase name="TestNG_Assertion_assertNotEquals" time="4.069" classname="testng_assignment.TestNG_Assertion">
    <failure type="java.lang.AssertionError" message="The assertNotEquals value is matched  :   did not expect [1] but found [1]">
      <![CDATA[java.lang.AssertionError: The assertNotEquals value is matched  :   did not expect [1] but found [1]
at org.testng.Assert.fail(Assert.java:97)
at org.testng.Assert.assertNotEquals(Assert.java:1399)
at testng_assignment.TestNG_Assertion.TestNG_Assertion_assertNotEquals(TestNG_Assertion.java:46)
at sun.reflect.NativeMethodAccessorImpl.invoke0(Native Method)
at sun.reflect.NativeMethodAccessorImpl.invoke(Unknown Source)
at sun.reflect.DelegatingMethodAccessorImpl.invoke(Unknown Source)
at java.lang.reflect.Method.invoke(Unknown Source)
at org.testng.internal.MethodInvocationHelper.invokeMethod(MethodInvocationHelper.java:134)
at org.testng.internal.TestInvoker.invokeMethod(TestInvoker.java:597)
at org.testng.internal.TestInvoker.invokeTestMethod(TestInvoker.java:173)
at org.testng.internal.MethodRunner.runInSequence(MethodRunner.java:46)
at org.testng.internal.TestInvoker$MethodInvocationAgent.invoke(TestInvoker.java:816)
at org.testng.internal.TestInvoker.invokeTestMethods(TestInvoker.java:146)
at org.testng.internal.TestMethodWorker.invokeTestMethods(TestMethodWorker.java:146)
at org.testng.internal.TestMethodWorker.run(TestMethodWorker.java:128)
at java.util.concurrent.ThreadPoolExecutor.runWorker(Unknown Source)
at java.util.concurrent.ThreadPoolExecutor$Worker.run(Unknown Source)
at java.lang.Thread.run(Unknown Source)
]]>
    </failure>
  </testcase> <!-- TestNG_Assertion_assertNotEquals -->
  <system-out>
26-Jun-2020 01:56:02 AM : java.lang.AssertionError: The assertNotEquals value is matched  :   did not expect [1] but found [1]
	at org.testng.Assert.fail(Assert.java:97)
	at org.testng.Assert.assertNotEquals(Assert.java:1399)
	at testng_assignment.TestNG_Assertion.TestNG_Assertion_assertNotEquals(TestNG_Assertion.java:46)
	at sun.reflect.NativeMethodAccessorImpl.invoke0(Native Method)
	at sun.reflect.NativeMethodAccessorImpl.invoke(Unknown Source)
	at sun.reflect.DelegatingMethodAccessorImpl.invoke(Unknown Source)
	at java.lang.reflect.Method.invoke(Unknown Source)
	at org.testng.internal.MethodInvocationHelper.invokeMethod(MethodInvocationHelper.java:134)
	at org.testng.internal.TestInvoker.invokeMethod(TestInvoker.java:597)
	at org.testng.internal.TestInvoker.invokeTestMethod(TestInvoker.java:173)
	at org.testng.internal.MethodRunner.runInSequence(MethodRunner.java:46)
	at org.testng.internal.TestInvoker$MethodInvocationAgent.invoke(TestInvoker.java:816)
	at org.testng.internal.TestInvoker.invokeTestMethods(TestInvoker.java:146)
	at org.testng.internal.TestMethodWorker.invokeTestMethods(TestMethodWorker.java:146)
	at org.testng.internal.TestMethodWorker.run(TestMethodWorker.java:128)
	at java.util.concurrent.ThreadPoolExecutor.runWorker(Unknown Source)
	at java.util.concurrent.ThreadPoolExecutor$Worker.run(Unknown Source)
	at java.lang.Thread.run(Unknown Source)
  </system-out>
</testsuite> <!-- testng_assignment.TestNG_Assertion -->
